src/base/loader/elf_object.cc:129: panic: gelf_getphdr failed for segment 0.
Memory Usage: 167156 KBytes
Program aborted at tick 0
--- BEGIN LIBC BACKTRACE ---
/home/ubuntu/gem5-ssbse-challenge-2023/build/X86/gem5.opt(+0x38b2663)[0x55ccedaf2663]
/home/ubuntu/gem5-ssbse-challenge-2023/build/X86/gem5.opt(+0x39060c9)[0x55ccedb460c9]
/lib/x86_64-linux-gnu/libpthread.so.0(+0x14420)[0x7fc5dca82420]
/lib/x86_64-linux-gnu/libc.so.6(gsignal+0xcb)[0x7fc5dbbb800b]
/lib/x86_64-linux-gnu/libc.so.6(abort+0x12b)[0x7fc5dbb97859]
/home/ubuntu/gem5-ssbse-challenge-2023/build/X86/gem5.opt(+0xab5f45)[0x55cceacf5f45]
/home/ubuntu/gem5-ssbse-challenge-2023/build/X86/gem5.opt(+0xc465e4)[0x55cceae865e4]
/home/ubuntu/gem5-ssbse-challenge-2023/build/X86/gem5.opt(+0xc46fb9)[0x55cceae86fb9]
/home/ubuntu/gem5-ssbse-challenge-2023/build/X86/gem5.opt(+0xc511b7)[0x55cceae911b7]
/home/ubuntu/gem5-ssbse-challenge-2023/build/X86/gem5.opt(+0x18023b8)[0x55cceba423b8]
/home/ubuntu/gem5-ssbse-challenge-2023/build/X86/gem5.opt(+0xa626b9)[0x55cceaca26b9]
/lib/x86_64-linux-gnu/libpython3.8.so.1.0(+0x2a8748)[0x7fc5dcd3b748]
/lib/x86_64-linux-gnu/libpython3.8.so.1.0(_PyObject_MakeTpCall+0xab)[0x7fc5dcd3bb2b]
/lib/x86_64-linux-gnu/libpython3.8.so.1.0(+0x74df3)[0x7fc5dcb07df3]
/lib/x86_64-linux-gnu/libpython3.8.so.1.0(_PyEval_EvalFrameDefault+0x7d86)[0x7fc5dcb0fef6]
/lib/x86_64-linux-gnu/libpython3.8.so.1.0(_PyEval_EvalCodeWithName+0x8fb)[0x7fc5dcc5de4b]
/lib/x86_64-linux-gnu/libpython3.8.so.1.0(_PyFunction_Vectorcall+0x94)[0x7fc5dcd3b124]
/lib/x86_64-linux-gnu/libpython3.8.so.1.0(+0x2a8dba)[0x7fc5dcd3bdba]
/lib/x86_64-linux-gnu/libpython3.8.so.1.0(+0x74d6d)[0x7fc5dcb07d6d]
/lib/x86_64-linux-gnu/libpython3.8.so.1.0(_PyEval_EvalFrameDefault+0x7d86)[0x7fc5dcb0fef6]
/lib/x86_64-linux-gnu/libpython3.8.so.1.0(_PyEval_EvalCodeWithName+0x8fb)[0x7fc5dcc5de4b]
/lib/x86_64-linux-gnu/libpython3.8.so.1.0(_PyFunction_Vectorcall+0x94)[0x7fc5dcd3b124]
/lib/x86_64-linux-gnu/libpython3.8.so.1.0(+0x2a8dba)[0x7fc5dcd3bdba]
/lib/x86_64-linux-gnu/libpython3.8.so.1.0(+0x74d6d)[0x7fc5dcb07d6d]
/lib/x86_64-linux-gnu/libpython3.8.so.1.0(_PyEval_EvalFrameDefault+0x7d86)[0x7fc5dcb0fef6]
/lib/x86_64-linux-gnu/libpython3.8.so.1.0(_PyEval_EvalCodeWithName+0x8fb)[0x7fc5dcc5de4b]
/lib/x86_64-linux-gnu/libpython3.8.so.1.0(_PyFunction_Vectorcall+0x94)[0x7fc5dcd3b124]
/lib/x86_64-linux-gnu/libpython3.8.so.1.0(+0x2a8dba)[0x7fc5dcd3bdba]
/lib/x86_64-linux-gnu/libpython3.8.so.1.0(+0x74d6d)[0x7fc5dcb07d6d]
/lib/x86_64-linux-gnu/libpython3.8.so.1.0(_PyEval_EvalFrameDefault+0x45a3)[0x7fc5dcb0c713]
/lib/x86_64-linux-gnu/libpython3.8.so.1.0(_PyEval_EvalCodeWithName+0x8fb)[0x7fc5dcc5de4b]
/lib/x86_64-linux-gnu/libpython3.8.so.1.0(PyEval_EvalCodeEx+0x42)[0x7fc5dcc5e1d2]
--- END LIBC BACKTRACE ---
For more info on how to address this issue, please visit https://www.gem5.org/documentation/general_docs/common-errors/ 

./mine-crash.sh: line 21: 530846 Aborted                 $gem5 $gem5_script --isa X86 --input $txt_file
