gem5 has encountered a segmentation fault!

--- BEGIN LIBC BACKTRACE ---
/home/ubuntu/gem5-ssbse-challenge-2023/build/X86/gem5.opt(+0x38b2663)[0x55e6ea3f5663]
/home/ubuntu/gem5-ssbse-challenge-2023/build/X86/gem5.opt(+0x3905eb5)[0x55e6ea448eb5]
/lib/x86_64-linux-gnu/libpthread.so.0(+0x14420)[0x7f97b1b82420]
/lib/x86_64-linux-gnu/libc.so.6(+0x1886e5)[0x7f97b0dfd6e5]
/home/ubuntu/gem5-ssbse-challenge-2023/build/X86/gem5.opt(+0xa3923c)[0x55e6e757c23c]
/home/ubuntu/gem5-ssbse-challenge-2023/build/X86/gem5.opt(+0xc3ee13)[0x55e6e7781e13]
/home/ubuntu/gem5-ssbse-challenge-2023/build/X86/gem5.opt(+0xc44b44)[0x55e6e7787b44]
/home/ubuntu/gem5-ssbse-challenge-2023/build/X86/gem5.opt(+0xc46fb9)[0x55e6e7789fb9]
/home/ubuntu/gem5-ssbse-challenge-2023/build/X86/gem5.opt(+0xc511b7)[0x55e6e77941b7]
/home/ubuntu/gem5-ssbse-challenge-2023/build/X86/gem5.opt(+0x18023b8)[0x55e6e83453b8]
/home/ubuntu/gem5-ssbse-challenge-2023/build/X86/gem5.opt(+0xa626b9)[0x55e6e75a56b9]
/lib/x86_64-linux-gnu/libpython3.8.so.1.0(+0x2a8748)[0x7f97b1e3b748]
/lib/x86_64-linux-gnu/libpython3.8.so.1.0(_PyObject_MakeTpCall+0xab)[0x7f97b1e3bb2b]
/lib/x86_64-linux-gnu/libpython3.8.so.1.0(+0x74df3)[0x7f97b1c07df3]
/lib/x86_64-linux-gnu/libpython3.8.so.1.0(_PyEval_EvalFrameDefault+0x7d86)[0x7f97b1c0fef6]
/lib/x86_64-linux-gnu/libpython3.8.so.1.0(_PyEval_EvalCodeWithName+0x8fb)[0x7f97b1d5de4b]
/lib/x86_64-linux-gnu/libpython3.8.so.1.0(_PyFunction_Vectorcall+0x94)[0x7f97b1e3b124]
/lib/x86_64-linux-gnu/libpython3.8.so.1.0(+0x2a8dba)[0x7f97b1e3bdba]
/lib/x86_64-linux-gnu/libpython3.8.so.1.0(+0x74d6d)[0x7f97b1c07d6d]
/lib/x86_64-linux-gnu/libpython3.8.so.1.0(_PyEval_EvalFrameDefault+0x7d86)[0x7f97b1c0fef6]
/lib/x86_64-linux-gnu/libpython3.8.so.1.0(_PyEval_EvalCodeWithName+0x8fb)[0x7f97b1d5de4b]
/lib/x86_64-linux-gnu/libpython3.8.so.1.0(_PyFunction_Vectorcall+0x94)[0x7f97b1e3b124]
/lib/x86_64-linux-gnu/libpython3.8.so.1.0(+0x2a8dba)[0x7f97b1e3bdba]
/lib/x86_64-linux-gnu/libpython3.8.so.1.0(+0x74d6d)[0x7f97b1c07d6d]
/lib/x86_64-linux-gnu/libpython3.8.so.1.0(_PyEval_EvalFrameDefault+0x7d86)[0x7f97b1c0fef6]
/lib/x86_64-linux-gnu/libpython3.8.so.1.0(_PyEval_EvalCodeWithName+0x8fb)[0x7f97b1d5de4b]
/lib/x86_64-linux-gnu/libpython3.8.so.1.0(_PyFunction_Vectorcall+0x94)[0x7f97b1e3b124]
/lib/x86_64-linux-gnu/libpython3.8.so.1.0(+0x2a8dba)[0x7f97b1e3bdba]
/lib/x86_64-linux-gnu/libpython3.8.so.1.0(+0x74d6d)[0x7f97b1c07d6d]
/lib/x86_64-linux-gnu/libpython3.8.so.1.0(_PyEval_EvalFrameDefault+0x45a3)[0x7f97b1c0c713]
/lib/x86_64-linux-gnu/libpython3.8.so.1.0(_PyEval_EvalCodeWithName+0x8fb)[0x7f97b1d5de4b]
/lib/x86_64-linux-gnu/libpython3.8.so.1.0(PyEval_EvalCodeEx+0x42)[0x7f97b1d5e1d2]
--- END LIBC BACKTRACE ---
For more info on how to address this issue, please visit https://www.gem5.org/documentation/general_docs/common-errors/ 

./mine-crash.sh: line 21: 528154 Segmentation fault      $gem5 $gem5_script --isa X86 --input $txt_file
